Workbook

Sheet ADD
E2: All Cell Area
A3: Number of Rows | B3: 2 | E3: Total Width | F3: =(B22*B4)/B3 -> 22.88
A4: Cell Count | B4: 8 | E4: Total Height | F4: =0.4 + (B3 * 1.71) + ((B3 -1)*0.8) + 0.4 -> 5.02
A6: Cell Dimensions | E6: Row Calculation
A7: PR Boundary Width | B7: 5.6 | E7: Total Width | F7: =F3 -> 22.88
A8: PR Boundary Height | B8: 1.71 | E8: Total Height | F8: =F4 -> 5.02
A9: Top Margin | B9: 0.12
A10: Bottom Margin | B10: 0.07 | E10: Bounding Box
A11: Left Margin | B11: 0.06 | E11: Total Width | F11: =F7+B19 -> 23.68
A12: Right Margin | B12: 0.06 | E12: Total Height | F12: =F4 +B19 -> 5.82
A13: Full Cell Width | B13: =B7+B11+B12 -> 5.72
A14: Full Cell Height | B14: 1.9 | E14: PR Region
E15: X | F15: =B18 -> 0.4
A16: λ (µm) | B16: 0.025 | E16: Y | F16: =B18-B10 -> 0.33
A17: One Routing Track - 8*λ (W) | B17: =B16*8 -> 0.2 | E17: Width | F17: =F3 -> 22.88
A18: Two Routing Track (W) | B18: =B17*2 -> 0.4 | E18: Height | F18: =0.4 + (B3 * 1.71) + ((B3 -1)*0.8) + 0.4 -> 5.02
A19: Four Routing Tracks (W) | B19: =B18*2 -> 0.8
A21: Check Cell Dimensions | E21: Bounding Box Polygon Vertices
A22: Full Cell Width (Check) | B22: =B7+B26+B27+B11+B12 -> 5.72 | F22: X1 | G22: Y1 | H22: 0 | I22: 0
A23: Full Cell Height (Check) | B23: =B8+B9+B10 -> 1.9 | F23: X2 | G23: Y2 | H23: =H22 -> 0 | I23: =F12 -> 5.82
F24: X3 | G24: Y3 | H24: =F11 -> 23.68 | I24: =F12 -> 5.82
F25: X4 | G25: Y4 | H25: =F11 -> 23.68 | I25: =I22 -> 0
E27: Bounding Box Area | F27: =F11*F12 -> 137.8176
E28: PR Region Area | F28: =F17*F18 -> 114.8576
E29: Bounding Box Utilization | F29: =F28/F27 -> 0.83340299
E31: Row Area | F31: =F7*F8 -> 114.8576
E32: Cells Area | F32: =F3*F4 -> 114.8576
E33: Row Utilization | F33: =(F32/F31) -> 1

Sheet MUX
E2: All Cell Area
A3: Number of Rows | B3: 2 | E3: Total Width | F3: =(B22*B4)/B3 -> 13.76
A4: Cell Count | B4: 16 | E4: Total Height | F4: =0.4 + (B3 * 1.71) + ((B3 -1)*0.8) + 0.4 -> 5.02
A6: Cell Dimensions | E6: Row Calculation
A7: PR Boundary Width | B7: 1.6 | E7: Total Width | F7: =F3 -> 13.76
A8: PR Boundary Height | B8: 1.71 | E8: Total Height | F8: =F4 -> 5.02
A9: Top Margin | B9: 0.12
A10: Bottom Margin | B10: 0.07 | E10: Bounding Box
A11: Left Margin | B11: 0.06 | E11: Total Width | F11: =F7+B19 -> 14.56
A12: Right Margin | B12: 0.06 | E12: Total Height | F12: =F4 +B19 -> 5.82
A13: Full Cell Width | B13: =B7+B11+B12 -> 1.72
A14: Full Cell Height | B14: =B8+B9+B10 -> 1.9 | E14: PR Region
E15: X | F15: =B18 -> 0.4
A16: λ (µm) | B16: 0.025 | E16: Y | F16: =B18-B10 -> 0.33
A17: One Routing Track - 8*λ (W) | B17: =B16*8 -> 0.2 | E17: Width | F17: =F3 -> 13.76
A18: Two Routing Track (W) | B18: =B17*2 -> 0.4 | E18: Height | F18: =F4 -> 5.02
A19: Four Routing Tracks (W) | B19: =B18*2 -> 0.8
A21: Check Cell Dimensions | E21: Bounding Box Polygon Vertices
A22: Full Cell Width (Check) | B22: =B13 -> 1.72 | F22: X1 | G22: Y1 | H22: 0 | I22: 0
A23: Full Cell Height (Check) | B23: =B14 -> 1.9 | F23: X2 | G23: Y2 | H23: =H22 -> 0 | I23: =F12 -> 5.82
F24: X3 | G24: Y3 | H24: =F11 -> 14.56 | I24: =F12 -> 5.82
F25: X4 | G25: Y4 | H25: =F11 -> 14.56 | I25: =I22 -> 0
E27: Bounding Box Area | F27: =F11*F12 -> 84.7392
E28: PR Region Area | F28: =F17*F18 -> 69.0752
E29: Bounding Box Utilization | F29: =F28/F27 -> 0.81515049
E31: Row Area | F31: =F7*F8 -> 69.0752
E32: Cells Area | F32: =F3*F4 -> 69.0752
E33: Row Utilization | F33: =(F32/F31) -> 1

Sheet ALU8
A2: ADD8 Cell Count | B2: =ADD!B4 -> 8 | E2: All Cell Area
E3: Total Width | F3: =B11+B25+B39+B44*B53 -> 102.45
A4: Cell Dimensions | E4: Total Height | F4: =0.4 + (B56 * 1.71) + ((B56 -1)*0.8) + 0.4 -> 30.12
A5: PR Boundary Width | B5: =ADD!F3 -> 22.88
A6: PR Boundary Height | B6: =ADD!F4 -> 5.02 | E6: Row Calculation
A7: Top Margin | B7: 0.12 | E7: Total Width | F7: =F3 -> 102.45
A8: Bottom Margin | B8: 0.07 | E8: Total Height | F8: =F4 -> 30.12
A9: Left Margin | B9: 0.06
A10: Right Margin | B10: 0.06 | E10: Bounding Box
A11: Full Cell Width | B11: =B5+B9+B10 -> 23 | E11: Total Width | F11: =F7+B68 -> 103.25
A12: Full Cell Height | B12: =B6+B7+B8 -> 5.21 | E12: Total Height | F12: =F4 + B68 -> 30.92
E14: PR Region
E15: X | F15: =B67 -> 0.4
A16: MULT Cell Count | B16: =MULT!B59 -> 209 | E16: Y | F16: =B67- MAX(B8,B22,B36) -> 0.33
E17: Width | F17: =F3 -> 102.45
A18: Cell Dimensions | E18: Height | F18: =F4 -> 30.12
A19: PR Boundary Width | B19: =MULT!F3 -> 60.41
A20: PR Boundary Height | B20: =MULT!F4 -> 20.08
A21: Top Margin | B21: 0.12 | E21: Bounding Box Polygon Vertices
A22: Bottom Margin | B22: 0.07 | F22: X1 | G22: Y1 | H22: 0 | I22: 0
A23: Left Margin | B23: 0.06 | F23: X2 | G23: Y2 | H23: =H22 -> 0 | I23: =F12 -> 30.92
A24: Right Margin | B24: 0.06 | F24: X3 | G24: Y3 | H24: =F11 -> 103.25 | I24: =F12 -> 30.92
A25: Full Cell Width | B25: =B19+B23+B24 -> 60.53 | F25: X4 | G25: Y4 | H25: =F11 -> 103.25 | I25: =I22 -> 0
A26: Full Cell Height | B26: =B20+B21+B22 -> 20.27
E27: Bounding Box Area | F27: =F11*F12 -> 3192.49
E28: PR Region Area | F28: =F17*F18 -> 3085.794
E29: Bounding Box Utilization | F29: =F28/F27 -> 0.96657907
A30: MUX Cell Count | B30: =MUX!B4 -> 16
E31: Row Area | F31: =F7*F8 -> 3085.794
A32: Cell Dimensions | E32: Cells Area | F32: =F3*F4 -> 3085.794
A33: PR Boundary Width | B33: =MUX!F3 -> 13.76 | E33: Row Utilization | F33: =(F32/F31) -> 1
A34: PR Boundary Height | B34: =MUX!F4 -> 5.02
A35: Top Margin | B35: 0.12
A36: Bottom Margin | B36: 0.07
A37: Left Margin | B37: 0.06
A38: Right Margin | B38: 0.06
A39: Full Cell Width | B39: =B33+B37+B38 -> 13.88
A40: Full Cell Height | B40: =B34+B35+B36 -> 5.21
A44: TIELO Cell Count | B44: 7
A46: Cell Dimensions
...

Sheet MULT
A1: {=1:69} -> 0
E2: All Cell Area
E3: Total Width | F3: =(B4 *B13 +B18 * B27 +B32 *B41 +B46 *B55)/B58 -> 60.41
A4: ADDDER Cell Count | B4: 64 | E4: Total Height | F4: =0.4 + (B58 * 1.71) + ((B58 -1)*0.8) + 0.4 -> 20.08
A6: Cell Dimensions | E6: Row Calculation
A7: PR Boundary Width | B7: 5.6 | E7: Total Width | F7: =F3 -> 60.41
A8: PR Boundary Height | B8: 1.71 | E8: Total Height | F8: =F4 -> 20.08
A9: Top Margin | B9: 0.12
A10: Bottom Margin | B10: 0.07 | E10: Bounding Box
A11: Left Margin | B11: 0.06 | E11: Total Width | F11: =F7+B78 -> 61.21
A12: Right Margin | B12: 0.06 | E12: Total Height | F12: =F4 + B78 -> 20.88
A13: Full Cell Width | B13: 5.72
A14: Full Cell Height | B14: 1.9 | E14: PR Region
E15: X | F15: =B77 -> 0.4
E16: Y | F16: =B77- MAX(B10,B24,B38) -> 0.33
E17: Width | F17: =F3 -> 60.41
A18: NAND Cell Count | B18: 64 | E18: Height | F18: =F4 -> 20.08
A20: Cell Dimensions
A21: PR Boundary Width | B21: 0.8 | E21: Bounding Box Polygon Vertices
A22: PR Boundary Height | B22: 1.71 | F22: X1 | G22: Y1 | H22: 0 | I22: 0
A23: Top Margin | B23: 0.12 | F23: X2 | G23: Y2 | H23: =H22 -> 0 | I23: =F12 -> 20.88
A24: Bottom Margin | B24: 0.07 | F24: X3 | G24: Y3 | H24: =F11 -> 61.21 | I24: =F12 -> 20.88
A25: Left Margin | B25: 0.06 | F25: X4 | G25: Y4 | H25: =F11 -> 61.21 | I25: =I22 -> 0
A26: Right Margin | B26: 0.06
A27: Full Cell Width | B27: 0.92 | E27: Bounding Box Area | F27: =F11*F12 -> 1278.0648
A28: Full Cell Height | B28: 1.9 | E28: PR Region Area | F28: =F17*F18 -> 1213.0328
E29: Bounding Box Utilization | F29: =F28/F27 -> 0.94911682
E31: Row Area | F31: =F7*F8 -> 1213.0328
A32: INV Cell Count | B32: 64 | E32: Cells Area | F32: =F3*F4 -> 1213.0328
E33: Row Utilization | F33: =(F32/F31) -> 1
A34: Cell Dimensions
A35: PR Boundary Width | B35: 0.6
A36: PR Boundary Height | B36: 1.71
A37: Top Margin | B37: 0.12
A38: Bottom Margin | B38: 0.07
A39: Left Margin | B39: 0.06
A40: Right Margin | B40: 0.06
A41: Full Cell Width | B41: 0.72
A42: Full Cell Height | B42: 1.9
A46: TIELO Cell Count | B46: 17
...

Sheet LFSR
A2: DFF Cell Count | B2: 16 | E2: All Cell Area
E3: Total Width | F3: =(B2*B11 +B16*B25+B30*B39+B44*B53)/B56 -> 46.01
A4: Cell Dimensions | E4: Total Height | F4: =0.4 + (B56 * 1.71) + ((B56 -1)*0.8) + 0.4 -> 10.04
A5: PR Boundary Width | B5: 8.4
A6: PR Boundary Height | B6: 1.71 | E6: Row Calculation
A7: Top Margin | B7: 0.12 | E7: Total Width | F7: =F3 -> 46.01
A8: Bottom Margin | B8: 0.07 | E8: Total Height | F8: =F4 -> 10.04
A9: Left Margin | B9: 0.06
A10: Right Margin | B10: 0.06 | E10: Bounding Box
A11: Full Cell Width | B11: =B5+B9+B10 -> 8.52 | E11: Total Width | F11: =F7+B68 -> 46.81
A12: Full Cell Height | B12: =B6+B7+B8 -> 1.9 | E12: Total Height | F12: =F4 + B68 -> 10.84
E14: PR Region
E15: X | F15: =B67 -> 0.4
A16: XOR Cell Count | B16: 3 | E16: Y | F16: =B67- MAX(B8,B22,B36) -> 0.33
E17: Width | F17: =F3 -> 46.01
A18: Cell Dimensions | E18: Height | F18: =F4 -> 10.04
A19: PR Boundary Width | B19: 2.2
A20: PR Boundary Height | B20: 1.71
A21: Top Margin | B21: 0.12 | E21: Bounding Box Polygon Vertices
A22: Bottom Margin | B22: 0.07 | F22: X1 | G22: Y1 | H22: 0 | I22: 0
A23: Left Margin | B23: 0.06 | F23: X2 | G23: Y2 | H23: =H22 -> 0 | I23: =F12 -> 10.84
A24: Right Margin | B24: 0.06 | F24: X3 | G24: Y3 | H24: =F11 -> 46.81 | I24: =F12 -> 10.84
A25: Full Cell Width | B25: =B19+B23+B24 -> 2.32 | F25: X4 | G25: Y4 | H25: =F11 -> 46.81 | I25: =I22 -> 0
A26: Full Cell Height | B26: =B20+B21+B22 -> 1.9
E27: Bounding Box Area | F27: =F11*F12 -> 507.4204
E28: PR Region Area | F28: =F17*F18 -> 461.9404
E29: Bounding Box Utilization | F29: =F28/F27 -> 0.91037018
A30: MUX Cell Count | B30: 17
E31: Row Area | F31: =F7*F8 -> 461.9404
A32: Cell Dimensions | E32: Cells Area | F32: =F3*F4 -> 461.9404
A33: PR Boundary Width | B33: 1.6 | E33: Row Utilization | F33: =(F32/F31) -> 1
A34: PR Boundary Height | B34: 1.71
A35: Top Margin | B35: 0.12
A36: Bottom Margin | B36: 0.07
A37: Left Margin | B37: 0.06
A38: Right Margin | B38: 0.06
A39: Full Cell Width | B39: =B33+B37+B38 -> 1.72
A40: Full Cell Height | B40: =B34+B35+B36 -> 1.9
A44: TIELO Cell Count | B44: 16
A46: Cell Dimensions
...

Sheet SISR
A2: DFF Cell Count | B2: 16 | E2: All Cell Area | I2: Number of Rows | J2: 4
E3: Total Width | F3: =(B2*B11 +B16*B25+B30*B39+B44*B53)/J2 -> 46.59 | I3: Total Cell Count | J3: =B2+B16+B30+B44+B59+B72 -> 55
A4: Cell Dimensions | E4: Total Height | F4: =0.4 + (J2 * 1.71) + ((J2 -1)*0.8) + 0.4 -> 10.04
A5: PR Boundary Width | B5: 8.4
A6: PR Boundary Height | B6: 1.71 | E6: Row Calculation
A7: Top Margin | B7: 0.12 | E7: Total Width | F7: =F3 -> 46.59
A8: Bottom Margin | B8: 0.07 | E8: Total Height | F8: =F4 -> 10.04 | I8: λ (µm) | J8: 0.025
A9: Left Margin | B9: 0.06 | I9: One Routing Track - 8*λ (W) | J9: =J8*8 -> 0.2
A10: Right Margin | B10: 0.06 | E10: Bounding Box | I10: Two Routing Track (W) | J10: =J9*2 -> 0.4
A11: Full Cell Width | B11: =B5+B9+B10 -> 8.52 | E11: Total Width | F11: =F7+J11 -> 47.39 | I11: Four Routing Tracks (W) | J11: =J10*2 -> 0.8
A12: Full Cell Height | B12: =B6+B7+B8 -> 1.9 | E12: Total Height | F12: =F4 + J11 -> 10.84
E14: PR Region
E15: X | F15: =J10 -> 0.4
A16: XOR Cell Count | B16: 4 | E16: Y | F16: =J10- MAX(B8,B22,B36) -> 0.33
E17: Width | F17: =F3 -> 46.59
A18: Cell Dimensions | E18: Height | F18: =F4 -> 10.04
A19: PR Boundary Width | B19: 2.2
A20: PR Boundary Height | B20: 1.71
A21: Top Margin | B21: 0.12 | E21: Bounding Box Polygon Vertices
A22: Bottom Margin | B22: 0.07 | F22: X1 | G22: Y1 | H22: 0 | I22: 0
A23: Left Margin | B23: 0.06 | F23: X2 | G23: Y2 | H23: =H22 -> 0 | I23: =F12 -> 10.84
A24: Right Margin | B24: 0.06 | F24: X3 | G24: Y3 | H24: =F11 -> 47.39 | I24: =F12 -> 10.84
A25: Full Cell Width | B25: =B19+B23+B24 -> 2.32 | F25: X4 | G25: Y4 | H25: =F11 -> 47.39 | I25: =I22 -> 0
A26: Full Cell Height | B26: =B20+B21+B22 -> 1.9
E27: Bounding Box Area | F27: =F11*F12 -> 513.7076
E28: PR Region Area | F28: =F17*F18 -> 467.7636
E29: Bounding Box Utilization | F29: =F28/F27 -> 0.91056391
A30: MUX Cell Count | B30: 17
E31: Row Area | F31: =F7*F8 -> 467.7636
A32: Cell Dimensions | E32: Cells Area | F32: =F3*F4 -> 467.7636
A33: PR Boundary Width | B33: 1.6 | E33: Row Utilization | F33: =(F32/F31) -> 1
A34: PR Boundary Height | B34: 1.71
A35: Top Margin | B35: 0.12
A36: Bottom Margin | B36: 0.07
A37: Left Margin | B37: 0.06
A38: Right Margin | B38: 0.06
A39: Full Cell Width | B39: =B33+B37+B38 -> 1.72
A40: Full Cell Height | B40: =B34+B35+B36 -> 1.9
A44: TIELO Cell Count | B44: 16
A46: Cell Dimensions
...

Sheet NAND16
E2: All Cell Area | I2: Number of Rows | J2: 2
E3: Total Width | F3: =(B6*B15 +B19*B28)/J2 -> 13.7 | I3: Total Cell Count | J3: 3
E4: Total Height | F4: =0.4 + (J2 * 1.71) + ((J2 -1)*0.8) + 0.4 -> 5.02
A6: NAND Cell Count | B6: 29 | E6: Row Calculation
E7: Total Width | F7: =F3 -> 13.7
A8: Cell Dimensions | E8: Total Height | F8: =F4 -> 5.02 | I8: λ (µm) | J8: 0.025
A9: PR Boundary Width | B9: 0.8 | I9: One Routing Track - 8*λ (W) | J9: =J8*8 -> 0.2
A10: PR Boundary Height | B10: 1.71 | E10: Bounding Box | I10: Two Routing Track (W) | J10: =J9*2 -> 0.4
A11: Top Margin | B11: 0.12 | E11: Total Width | F11: =F7+J11 -> 14.5 | I11: Four Routing Tracks (W) | J11: =J10*2 -> 0.8
A12: Bottom Margin | B12: 0.07 | E12: Total Height | F12: =F4 + J11 -> 5.82
A13: Left Margin | B13: 0.06
A14: Right Margin | B14: 0.06 | E14: PR Region
A15: Full Cell Width | B15: 0.92 | E15: X | F15: =J10 -> 0.4
A16: Full Cell Height | B16: 1.9 | E16: Y | F16: =J10- B12 -> 0.33
E17: Width | F17: =F3 -> 13.7
E18: Height | F18: =F4 -> 5.02
A19: INV Cell Count | B19: 1
A21: Cell Dimensions | E21: Bounding Box Polygon Vertices
A22: PR Boundary Width | B22: 0.6 | F22: X1 | G22: Y1 | H22: 0 | I22: 0
A23: PR Boundary Height | B23: 1.71 | F23: X2 | G23: Y2 | H23: =H22 -> 0 | I23: =F12 -> 5.82
A24: Top Margin | B24: 0.12 | F24: X3 | G24: Y3 | H24: =F11 -> 14.5 | I24: =F12 -> 5.82
A25: Bottom Margin | B25: 0.07 | F25: X4 | G25: Y4 | H25: =F11 -> 14.5 | I25: =I22 -> 0
A26: Left Margin | B26: 0.06
A27: Right Margin | B27: 0.06 | E27: Bounding Box Area | F27: =F11*F12 -> 84.39
A28: Full Cell Width | B28: 0.72 | E28: PR Region Area | F28: =F17*F18 -> 68.774
A29: Full Cell Height | B29: 1.9 | E29: Bounding Box Utilization | F29: =F28/F27 -> 0.81495438
A31: Total cell count | B31: =B6+B19 -> 30 | E31: Row Area | F31: =F7*F8 -> 68.774
E32: Cells Area | F32: =F3*F4 -> 68.774
E33: Row Utilization | F33: =(F32/F31) -> 1

Sheet ALU_BIST
A2: ALU Cell Count | B2: 1 | C2: ='ALU8'!B57 -> 240 | E2: All Cell Area
E3: Total Width | F3: =MAX(B11,B25,B39,B52)+ MIN(B11,B25,B39,B52) -> 117.25 | I3: Number of Rows | J3: 3
A4: Cell Dimensions | E4: Total Height | F4: =0.4+(B12*1.71)+((B12-1)*0.8)+0.4 -> 78.0861 | I4: Total Cell Count | J4: 5
A5: PR Boundary Width | B5: ='ALU8'!F3 -> 102.45
A6: PR Boundary Height | B6: ='ALU8'!F12 -> 30.92 | E6: Row Calculation
A7: Top Margin | B7: 0.12 | E7: Total Width | F7: =F3 -> 117.25
A8: Bottom Margin | B8: 0.07 | E8: Total Height | F8: =F4 -> 78.0861
A9: Left Margin | B9: 0.06 | I9: λ (µm) | J9: 0.025
A10: Right Margin | B10: 0.06 | E10: Bounding Box | I10: One Routing Track - 8*λ (W) | J10: =J9*8 -> 0.2
A11: Full Cell Width | B11: =B5+B9+B10 -> 102.57 | E11: Total Width | F11: =F7+J12 -> 118.05 | I11: Two Routing Track (W) | J11: =J10*2 -> 0.4
A12: Full Cell Height | B12: =B6+B7+B8 -> 31.11 | E12: Total Height | F12: =F4 + J12 -> 78.8861 | I12: Four Routing Tracks (W) | J12: =J11*2 -> 0.8
E14: PR Region
E15: X | F15: =J11*4 -> 1.6
A16: LFSR Cell Count | B16: 1 | C16: =LFSR!B57 -> 52 | E16: Y | F16: =F15- B8 -> 1.53
E17: Width | F17: =F3 -> 117.25
A18: Cell Dimensions | E18: Height | F18: =F4 -> 78.0861
A19: PR Boundary Width | B19: =LFSR!F11 -> 46.81
A20: PR Boundary Height | B20: =LFSR!F12 -> 10.84
A21: Top Margin | B21: 0.12 | E21: Bounding Box Polygon Vertices
A22: Bottom Margin | B22: 0.07 | F22: X1 | G22: Y1 | H22: 0 | I22: 0
A23: Left Margin | B23: 0.06 | F23: X2 | G23: Y2 | H23: =H22 -> 0 | I23: =F12 -> 78.8861
A24: Right Margin | B24: 0.06 | F24: X3 | G24: Y3 | H24: =F11 -> 118.05 | I24: =F12 -> 78.8861
A25: Full Cell Width | B25: =B19+B23+B24 -> 46.93 | F25: X4 | G25: Y4 | H25: =F11 -> 118.05 | I25: =I22 -> 0
A26: Full Cell Height | B26: =B20+B21+B22 -> 11.03
E27: Bounding Box Area | F27: =F11*F12 -> 9312.5041
E28: PR Region Area | F28: =F17*F18 -> 9155.5952
E29: Bounding Box Utilization | F29: =F28/F27 -> 0.98315073
A30: MUX Cell Count | B30: 1 | C30: =MUX!B4 -> 16
E31: Row Area | F31: =F7*F8 -> 9155.5952
A32: Cell Dimensions | E32: Cells Area | F32: =F3*F4 -> 9155.5952
A33: PR Boundary Width | B33: =MUX!F11 -> 14.56 | E33: Row Utilization | F33: =(F32/F31) -> 1
A34: PR Boundary Height | B34: =MUX!F12 -> 5.82
A35: Top Margin | B35: 0.12
A36: Bottom Margin | B36: 0.07
A37: Left Margin | B37: 0.06
A38: Right Margin | B38: 0.06
A39: Full Cell Width | B39: =B33+B37+B38 -> 14.68
A40: Full Cell Height | B40: =B34+B35+B36 -> 6.01
A43: SISR Cell Count | B43: 1 | C43: =SISR!B85 -> 55
A45: Cell Dimensions
...

Sheet Sheet1
